{"trial_id": "132", "hyperparameters": {"space": [{"class_name": "Int", "config": {"name": "filters", "default": null, "conditions": [], "min_value": 10, "max_value": 150, "step": 5, "sampling": "linear"}}, {"class_name": "Choice", "config": {"name": "pool_size", "default": 2, "conditions": [], "values": [2, 3], "ordered": true}}, {"class_name": "Choice", "config": {"name": "learning_rate", "default": 0.01, "conditions": [], "values": [0.01, 0.001, 0.0001], "ordered": true}}], "values": {"filters": 150, "pool_size": 2, "learning_rate": 0.001}}, "metrics": {"metrics": {}}, "score": null, "best_step": 0, "status": "FAILED", "message": "Traceback (most recent call last):\n  File \"/opt/anaconda3/lib/python3.11/site-packages/keras_tuner/src/engine/base_tuner.py\", line 274, in _try_run_and_update_trial\n    self._run_and_update_trial(trial, *fit_args, **fit_kwargs)\n  File \"/opt/anaconda3/lib/python3.11/site-packages/keras_tuner/src/engine/base_tuner.py\", line 239, in _run_and_update_trial\n    results = self.run_trial(trial, *fit_args, **fit_kwargs)\n              ^^^^^^^^^^^^^^^^^^^^^^^^^^^^^^^^^^^^^^^^^^^^^^\n  File \"/opt/anaconda3/lib/python3.11/site-packages/keras_tuner/src/engine/tuner.py\", line 314, in run_trial\n    obj_value = self._build_and_fit_model(trial, *args, **copied_kwargs)\n                ^^^^^^^^^^^^^^^^^^^^^^^^^^^^^^^^^^^^^^^^^^^^^^^^^^^^^^^^\n  File \"/opt/anaconda3/lib/python3.11/site-packages/keras_tuner/src/engine/tuner.py\", line 233, in _build_and_fit_model\n    results = self.hypermodel.fit(hp, model, *args, **kwargs)\n              ^^^^^^^^^^^^^^^^^^^^^^^^^^^^^^^^^^^^^^^^^^^^^^^\n  File \"/opt/anaconda3/lib/python3.11/site-packages/keras_tuner/src/engine/hypermodel.py\", line 149, in fit\n    return model.fit(*args, **kwargs)\n           ^^^^^^^^^^^^^^^^^^^^^^^^^^\n  File \"/opt/anaconda3/lib/python3.11/site-packages/keras/src/utils/traceback_utils.py\", line 122, in error_handler\n    raise e.with_traceback(filtered_tb) from None\n  File \"/opt/anaconda3/lib/python3.11/site-packages/tensorflow/python/eager/execute.py\", line 59, in quick_execute\n    except TypeError as e:\ntensorflow.python.framework.errors_impl.InvalidArgumentError: Graph execution error:\n\nDetected at node adam/AssignSubVariableOp_7 defined at (most recent call last):\n  File \"<frozen runpy>\", line 198, in _run_module_as_main\n\n  File \"<frozen runpy>\", line 88, in _run_code\n\n  File \"/opt/anaconda3/lib/python3.11/site-packages/ipykernel_launcher.py\", line 17, in <module>\n\n  File \"/opt/anaconda3/lib/python3.11/site-packages/traitlets/config/application.py\", line 992, in launch_instance\n\n  File \"/opt/anaconda3/lib/python3.11/site-packages/ipykernel/kernelapp.py\", line 701, in start\n\n  File \"/opt/anaconda3/lib/python3.11/site-packages/tornado/platform/asyncio.py\", line 195, in start\n\n  File \"/opt/anaconda3/lib/python3.11/asyncio/base_events.py\", line 607, in run_forever\n\n  File \"/opt/anaconda3/lib/python3.11/asyncio/base_events.py\", line 1922, in _run_once\n\n  File \"/opt/anaconda3/lib/python3.11/asyncio/events.py\", line 80, in _run\n\n  File \"/opt/anaconda3/lib/python3.11/site-packages/ipykernel/kernelbase.py\", line 534, in dispatch_queue\n\n  File \"/opt/anaconda3/lib/python3.11/site-packages/ipykernel/kernelbase.py\", line 523, in process_one\n\n  File \"/opt/anaconda3/lib/python3.11/site-packages/ipykernel/kernelbase.py\", line 429, in dispatch_shell\n\n  File \"/opt/anaconda3/lib/python3.11/site-packages/ipykernel/kernelbase.py\", line 767, in execute_request\n\n  File \"/opt/anaconda3/lib/python3.11/site-packages/ipykernel/ipkernel.py\", line 429, in do_execute\n\n  File \"/opt/anaconda3/lib/python3.11/site-packages/ipykernel/zmqshell.py\", line 549, in run_cell\n\n  File \"/opt/anaconda3/lib/python3.11/site-packages/IPython/core/interactiveshell.py\", line 3051, in run_cell\n\n  File \"/opt/anaconda3/lib/python3.11/site-packages/IPython/core/interactiveshell.py\", line 3106, in _run_cell\n\n  File \"/opt/anaconda3/lib/python3.11/site-packages/IPython/core/async_helpers.py\", line 129, in _pseudo_sync_runner\n\n  File \"/opt/anaconda3/lib/python3.11/site-packages/IPython/core/interactiveshell.py\", line 3311, in run_cell_async\n\n  File \"/opt/anaconda3/lib/python3.11/site-packages/IPython/core/interactiveshell.py\", line 3493, in run_ast_nodes\n\n  File \"/opt/anaconda3/lib/python3.11/site-packages/IPython/core/interactiveshell.py\", line 3553, in run_code\n\n  File \"/var/folders/p3/mn5l_nm52fdg2ns2zst4nf9w0000gn/T/ipykernel_2009/954924382.py\", line 131, in <module>\n\n  File \"/var/folders/p3/mn5l_nm52fdg2ns2zst4nf9w0000gn/T/ipykernel_2009/954924382.py\", line 102, in fit_and_evaluate\n\n  File \"/opt/anaconda3/lib/python3.11/site-packages/keras_tuner/src/engine/base_tuner.py\", line 234, in search\n\n  File \"/opt/anaconda3/lib/python3.11/site-packages/keras_tuner/src/engine/base_tuner.py\", line 274, in _try_run_and_update_trial\n\n  File \"/opt/anaconda3/lib/python3.11/site-packages/keras_tuner/src/engine/base_tuner.py\", line 239, in _run_and_update_trial\n\n  File \"/opt/anaconda3/lib/python3.11/site-packages/keras_tuner/src/engine/tuner.py\", line 314, in run_trial\n\n  File \"/opt/anaconda3/lib/python3.11/site-packages/keras_tuner/src/engine/tuner.py\", line 233, in _build_and_fit_model\n\n  File \"/opt/anaconda3/lib/python3.11/site-packages/keras_tuner/src/engine/hypermodel.py\", line 149, in fit\n\n  File \"/opt/anaconda3/lib/python3.11/site-packages/keras/src/utils/traceback_utils.py\", line 117, in error_handler\n\n  File \"/opt/anaconda3/lib/python3.11/site-packages/keras/src/backend/tensorflow/trainer.py\", line 314, in fit\n\n  File \"/opt/anaconda3/lib/python3.11/site-packages/keras/src/backend/tensorflow/trainer.py\", line 117, in one_step_on_iterator\n\n  File \"/opt/anaconda3/lib/python3.11/site-packages/keras/src/backend/tensorflow/trainer.py\", line 104, in one_step_on_data\n\n  File \"/opt/anaconda3/lib/python3.11/site-packages/keras/src/backend/tensorflow/trainer.py\", line 69, in train_step\n\n  File \"/opt/anaconda3/lib/python3.11/site-packages/keras/src/optimizers/base_optimizer.py\", line 281, in apply_gradients\n\n  File \"/opt/anaconda3/lib/python3.11/site-packages/keras/src/optimizers/base_optimizer.py\", line 350, in apply\n\n  File \"/opt/anaconda3/lib/python3.11/site-packages/keras/src/optimizers/base_optimizer.py\", line 404, in _backend_apply_gradients\n\n  File \"/opt/anaconda3/lib/python3.11/site-packages/keras/src/backend/tensorflow/optimizer.py\", line 119, in _backend_update_step\n\n  File \"/opt/anaconda3/lib/python3.11/site-packages/keras/src/backend/tensorflow/optimizer.py\", line 135, in _distributed_tf_update_step\n\n  File \"/opt/anaconda3/lib/python3.11/site-packages/keras/src/backend/tensorflow/optimizer.py\", line 132, in apply_grad_to_update_var\n\n  File \"/opt/anaconda3/lib/python3.11/site-packages/keras/src/optimizers/adam.py\", line 145, in update_step\n\n  File \"/opt/anaconda3/lib/python3.11/site-packages/keras/src/backend/tensorflow/optimizer.py\", line 73, in assign_sub\n\nCannot update variable with shape [1] using a Tensor with shape [0], shapes must be equal.\n\t [[{{node adam/AssignSubVariableOp_7}}]] [Op:__inference_one_step_on_iterator_555547]\n"}